Workbook

Sheet Winery Departments
A1: Winery | B1: Job Function / Department | C1: Count | E1: Winery | F1: LinkedIn Members | G1: Displayed Function Count Sum | H1: Displayed Sum / Members | I1: Note
A2: Purcari Wineries | B2: Operations | C2: 24 | E2: Purcari Wineries | F2: 103 | G2: =SUMIF('Winery Departments'!$A:$A,E2,'Winery Departments'!$C:$C) -> 72 | H2: =G2/F2 -> 0.69902913 | I2: =IF(G2>F2,"Department categories overlap","Displayed categories do not exceed total") -> Displayed categories do not exceed total
A3: Purcari Wineries | B3: Marketing | C3: 20 | E3: Cramele Recas | F3: 71 | G3: =SUMIF('Winery Departments'!$A:$A,E3,'Winery Departments'!$C:$C) -> 62 | H3: 0.87323944 | I3: Displayed categories do not exceed total
A4: Purcari Wineries | B4: Sales | C4: 14 | E4: Jidvei | F4: 116 | G4: =SUMIF('Winery Departments'!$A:$A,E4,'Winery Departments'!$C:$C) -> 73 | H4: 0.62931034 | I4: Displayed categories do not exceed total
A5: Purcari Wineries | B5: Accounting | C5: 7 | E5: Cramele Cotnari | F5: 23 | G5: =SUMIF('Winery Departments'!$A:$A,E5,'Winery Departments'!$C:$C) -> 21 | H5: 0.91304348 | I5: Displayed categories do not exceed total
A6: Purcari Wineries | B6: Human Resources | C6: 7 | E6: Beciul Domnesc | F6: 115 | G6: =SUMIF('Winery Departments'!$A:$A,E6,'Winery Departments'!$C:$C) -> 76 | H6: 0.66086957 | I6: Displayed categories do not exceed total
A7: Cramele Recas | B7: Sales | C7: 34 | E7: Crama Ceptura | F7: 9 | G7: =SUMIF('Winery Departments'!$A:$A,E7,'Winery Departments'!$C:$C) -> 8 | H7: 0.88888889 | I7: Displayed categories do not exceed total
A8: Cramele Recas | B8: Operations | C8: 16 | E8: Domeniile Averesti | F8: 10 | G8: =SUMIF('Winery Departments'!$A:$A,E8,'Winery Departments'!$C:$C) -> 11 | H8: 1.1 | I8: Department categories overlap
A9: Cramele Recas | B9: Business Development | C9: 5 | E9: Budureasca | F9: 39 | G9: =SUMIF('Winery Departments'!$A:$A,E9,'Winery Departments'!$C:$C) -> 32 | H9: 0.82051282 | I9: Displayed categories do not exceed total
A10: Cramele Recas | B10: Engineering | C10: 4 | E10: Tohani Romania | F10: 10 | G10: =SUMIF('Winery Departments'!$A:$A,E10,'Winery Departments'!$C:$C) -> 10 | H10: 1 | I10: Displayed categories do not exceed total
A11: Cramele Recas | B11: Marketing | C11: 3 | E11: Murfatlar | F11: 14 | G11: =SUMIF('Winery Departments'!$A:$A,E11,'Winery Departments'!$C:$C) -> 11 | H11: 0.78571429 | I11: Displayed categories do not exceed total
A12: Jidvei | B12: Sales | C12: 25 | E12: Davino Winery | F12: 9 | G12: =SUMIF('Winery Departments'!$A:$A,E12,'Winery Departments'!$C:$C) -> 11 | H12: 1.2222222 | I12: Department categories overlap
A13: Jidvei | B13: Operations | C13: 17 | E13: Domeniile Ostrov | F13: 10 | G13: =SUMIF('Winery Departments'!$A:$A,E13,'Winery Departments'!$C:$C) -> 9 | H13: 0.9 | I13: Displayed categories do not exceed total
A14: Jidvei | B14: Engineering | C14: 14 | E14: Casa de Vinuri Cotnari SA | F14: 17 | G14: =SUMIF('Winery Departments'!$A:$A,E14,'Winery Departments'!$C:$C) -> 16 | H14: 0.94117647 | I14: Displayed categories do not exceed total
... A16: Jidvei | B16: Administrative | C16: 8 | E16: Via Viticola | F16: 45 | G16: =SUMIF('Winery Departments'!$A:$A,E16,'Winery Departments'!$C:$C) -> 34 | H16: 0.75555556 | I16: Marketing company of Vintruvian Estates
A17: Cramele Cotnari | B17: Sales | C17: 15 | E17: Crama Gîrboiu | G17: =SUMIF('Winery Departments'!$A:$A,E17,'Winery Departments'!$C:$C) -> 0 | H17: =IFERROR(G17/F17,"") | I17: No LinkedIn capture available; BestJobs employer profile lists 6 alumni (checked 2026-08-21)
A18: Cramele Cotnari | B18: Marketing | C18: 3 | E18: Domeniile Vânju Mare | G18: =SUMIF('Winery Departments'!$A:$A,E18,'Winery Departments'!$C:$C) -> 0 | H18: =IFERROR(G18/F18,"") | I18: No LinkedIn capture available; BestJobs employer profile exists, alumni count not published (checked 2026-08-21)
A19: Cramele Cotnari | B19: Operations | C19: 1 | E19: Licorna WineHouse | G19: =SUMIF('Winery Departments'!$A:$A,E19,'Winery Departments'!$C:$C) -> 0 | H19: =IFERROR(G19/F19,"") | I19: No LinkedIn capture available; BestJobs employer profile lists 1 alumnus (checked 2026-08-21)
A20: Cramele Cotnari | B20: Program and Project Management | C20: 1 | E20: Gitana Winery | G20: =SUMIF('Winery Departments'!$A:$A,E20,'Winery Departments'!$C:$C) -> 0 | H20: =IFERROR(G20/F20,"") | I20: Moldovan producer — outside the Romanian LinkedIn capture. Four staff are named on the winery's own People page (checked 2026-08-21)
A21: Cramele Cotnari | B21: Research | C21: 1 | E21: Domeniile Sâmburești | G21: =SUMIF('Winery Departments'!$A:$A,E21,'Winery Departments'!$C:$C) -> 0 | H21: =IFERROR(G21/F21,"") | I21: No LinkedIn capture available; BestJobs employer profile lists 2 alumni (checked 2026-08-21)
A22: Beciul Domnesc | B22: Sales | C22: 34 | E22: Crama Rasova | G22: =SUMIF('Winery Departments'!$A:$A,E22,'Winery Departments'!$C:$C) -> 0 | H22: =IFERROR(G22/F22,"") | I22: No LinkedIn capture available; BestJobs employer profile lists 4 alumni (checked 2026-08-21)
A23: Beciul Domnesc | B23: Operations | C23: 14 | E23: Liliac Winery | G23: =SUMIF('Winery Departments'!$A:$A,E23,'Winery Departments'!$C:$C) -> 0 | H23: =IFERROR(G23/F23,"") | I23: No LinkedIn capture available; BestJobs employer profile for amb Wine Company lists 15 alumni (checked 2026-08-21)
A24: Beciul Domnesc | B24: Business Development | C24: 12 | E24: Crama Oprișor | G24: =SUMIF('Winery Departments'!$A:$A,E24,'Winery Departments'!$C:$C) -> 0 | H24: =IFERROR(G24/F24,"") | I24: No LinkedIn capture available; the winery publishes a full team page naming 14 staff, and a BestJobs employer profile exists (checked 2026-08-21)
A25: Beciul Domnesc | B25: Finance | C25: 9 | E25: Domeniile Săhăteni | G25: =SUMIF('Winery Departments'!$A:$A,E25,'Winery Departments'!$C:$C) -> 0 | H25: =IFERROR(G25/F25,"") | I25: No LinkedIn capture available; BestJobs employer profile lists 11 alumni (checked 2026-08-21)
A26: Beciul Domnesc | B26: Engineering | C26: 7 | E26: Crama 1000 de Chipuri | G26: =SUMIF('Winery Departments'!$A:$A,E26,'Winery Departments'!$C:$C) -> 0 | H26: =IFERROR(G26/F26,"") | I26: No LinkedIn capture available; BestJobs employer profile lists 2 alumni (checked 2026-08-21)
A27: Crama Ceptura | B27: Sales | C27: 5 | E27: Casa de Vinuri Negrini | G27: =SUMIF('Winery Departments'!$A:$A,E27,'Winery Departments'!$C:$C) -> 0 | H27: =IFERROR(G27/F27,"") | I27: No LinkedIn capture available; BestJobs employer profile exists, alumni count not published (checked 2026-08-21)
A28: Crama Ceptura | B28: Accounting | C28: 1 | E28: Petro Vaselo | G28: =SUMIF('Winery Departments'!$A:$A,E28,'Winery Departments'!$C:$C) -> 0 | H28: =IFERROR(G28/F28,"") | I28: No LinkedIn capture available; a BestJobs employer profile exists but is empty (checked 2026-08-21)
... A31: Domeniile Averesti | B31: Sales | C31: 7 | E31: SERVE Ceptura | G31: =SUMIF('Winery Departments'!$A:$A,E31,'Winery Departments'!$C:$C) -> 0 | H31: =IFERROR(G31/F31,"") | I31: No LinkedIn capture available; BestJobs employer profile lists 8 alumni (checked 2026-08-21). Part of Purcari Wineries since May 2026
A32: Domeniile Averesti | B32: Marketing | C32: 2
A33: Domeniile Averesti | B33: Business Development | C33: 1
A34: Domeniile Averesti | B34: Engineering | C34: 1
A35: Budureasca | B35: Sales | C35: 14
A36: Budureasca | B36: Operations | C36: 7
A37: Budureasca | B37: Marketing | C37: 5
A38: Budureasca | B38: Accounting | C38: 3
A39: Budureasca | B39: Information Technology | C39: 3
A40: Tohani Romania | B40: Operations | C40: 4
A41: Tohani Romania | B41: Sales | C41: 2
A42: Tohani Romania | B42: Engineering | C42: 2
A43: Tohani Romania | B43: Finance | C43: 1
...

Sheet Open Positions
A1: Winery | B1: Role / website finding | C1: Type | D1: Location | E1: Status | F1: Source / timing | G1: Details / application route | H1: Source URL
A2: Purcari Wineries | B2: Manager, Quality Management Systems | C2: Vacancy | D2: Chișinău; production-site travel | E2: Publicly advertised | F2: LinkedIn company post; ~2 weeks before 2026-08-18 | G2: ISO 9001/22000, audits, food safety and continuous improvement. Apply via hr@purcari.wine. | H2: https://www.linkedin.com/company/purcari-wineries-plc
A3: Purcari Wineries | B3: Project Development Manager (Financing & Investments) | C3: Vacancy | D3: Chișinău | E3: Publicly advertised | F3: LinkedIn company post; ~2 weeks before 2026-08-18 | G3: Financing, grants, investments and strategic project development. Apply via hr@purcari.wine. | H3: https://www.linkedin.com/company/purcari-wineries-plc
A4: Purcari Wineries | B4: Office Manager | C4: Vacancy | D4: Chișinău | E4: Recent posting; verify | F4: LinkedIn company post; ~2 months before 2026-08-18 | G4: Management-team support and daily office operations; the post may have closed. | H4: https://www.linkedin.com/company/purcari-wineries-plc
A5: Purcari Wineries | B5: Agronom | C5: Paid internship / early career | D5: Purcari, Moldova | E5: Listed; verify application window | F5: Official internship site checked 2026-08-18 | G5: Vineyard work planning, treatment/fertilization programs and team/resource coordination. | H5: https://internship.purcari.wine/
A6: Purcari Wineries | B6: IT Helpdesk | C6: Paid internship / early career | D6: Chișinău | E6: Listed; verify application window | F6: Official internship site checked 2026-08-18 | G6: Level-1 support, equipment availability, troubleshooting and application setup. | H6: https://internship.purcari.wine/
A7: Purcari Wineries | B7: HR Associate | C7: Paid internship / early career | D7: Chișinău | E7: Listed; verify application window | F7: Official internship site checked 2026-08-18 | G7: HR administration, personnel files, team-building support and HR projects. | H7: https://internship.purcari.wine/
A8: Purcari Wineries | B8: Trade Marketing Specialist | C8: Paid internship / early career | D8: Chișinău | E8: Listed; verify application window | F8: Official internship site checked 2026-08-18 | G8: Trade-marketing plans, promotional calendar, budgets and agency/vendor coordination. | H8: https://internship.purcari.wine/
A9: Purcari Wineries | B9: Guide — Château Purcari Tourist Complex | C9: Paid internship / early career | D9: Purcari, Ștefan Vodă | E9: Listed; verify application window | F9: Official internship site checked 2026-08-18 | G9: Visitor-facing role at the Château Purcari tourism complex. | H9: https://internship.purcari.wine/
A10: Jidvei | B10: Horticultural Engineer (COR 213230) | C10: Vacancy | D10: Jidvei / Cetatea de Baltă, Alba | E10: Recent posting; verify | F10: LinkedIn company post; ~3 months before 2026-08-18 | G10: Horticulture role advertised by the company; verify whether applications remain open. | H10: https://www.linkedin.com/company/jidvei
A11: Jidvei | B11: Brand Manager | C11: Vacancy | D11: Bucharest metropolitan area | E11: Recent posting; verify | F11: LinkedIn company post; ~5–6 months before 2026-08-18 | G11: Brand-management opening promoted twice; current acceptance status was not independently confirmed. | H11: https://www.linkedin.com/company/jidvei
A12: Jidvei | B12: Senior Event Manager | C12: Vacancy | D12: Bucharest metropolitan area | E12: Recent posting; verify | F12: LinkedIn company post; ~6 months before 2026-08-18 | G12: Event role aligned with Jidvei's large cultural and experiential calendar. | H12: https://www.linkedin.com/company/jidvei
... A62: SERVE Ceptura | B62: BestJobs employer profile (8 alumni) | C62: Job-board review | D62: Ceptura, Prahova | E62: Employer profile active; no open role visible at check | F62: BestJobs company profile checked 2026-08-21 | G62: No live listing was visible at check. Recruitment may move to the Purcari group route following the May 2026 acquisition. | H62: https://www.bestjobs.eu/company-profile/serve-ceptura

Sheet Campaign Evidence
A1: Winery | B1: Period | C1: Campaign / initiative | D1: Theme | E1: Channel / mechanic | F1: Pattern interpretation | G1: Source URL
A2: Jidvei | B2: 2026 | C2: Weinland Trails | D2: Experiential / tourism | E2: Running and cycling through vineyards, tastings, food and a charitable component | F2: A repeatable destination property linking wine with nature, community and active lifestyle. | G2: https://www.jidvei.ro/weinland-trails/
A3: Jidvei | B3: 2026 | C3: Spirit collection launch in Paris | D3: Product launch / prestige | E3: International reveal of the Spirit collection around the Paris cultural calendar | F3: Uses high-status international settings to premiumize new products. | G3: https://www.jidvei.ro/francezii-dedica-un-festival-culturii-romane-jidvei-aduce-un-omagiu-spiritului-romanesc-prin-lansarea-colectiei-spirit-in-premiera-la-paris/
A4: Jidvei | B4: 2025–2026 | C4: Strugurele de Aur | D4: Culture / heritage | E4: Recurring Romanian folklore festival supported and amplified by Jidvei | F4: Builds a durable association with Romanian music, dance and cultural heritage. | G4: https://www.jidvei.ro/festivalul-national-de-folclor-strugurele-de-aur-editia-xxi-3-7-septembrie-2025-blaj-si-jidvei/
A5: Jidvei | B5: 2024–2026 | C5: Romanian culture abroad | D5: Cultural diplomacy | E5: Brâncuși at Centre Pompidou, NASTY at Cannes and Paris Book Festival visibility | F5: Makes Romanian cultural prestige a recurring international communications platform. | G5: https://www.jidvei.ro/premiera-jidvei-este-vinul-oficial-al-vernisajului-celei-mai-ample-expozitii-brancusi-din-lume-organizata-la-centrul-pompidou-din-paris/
A6: Jidvei | B6: 2024 | C6: Romanian Olympic Team partnership | D6: Sports / national pride | E6: COSR partnership and Paris Olympics association | F6: Connects the brand to national representation, performance and major moments. | G6: https://www.jidvei.ro/jocurile-olimpice-de-la-paris-ne-au-adus-mai-aproape-de-sportivii-romani-printr-un-parteneriat-devenit-traditie-intre-asociatia-jidvei-viitor-prin-educatie-si-cosr/
A7: Jidvei | B7: Seasonal | C7: Must de la Jidvei | D7: Seasonal product | E7: Harvest-time must launch and availability communications | F7: Uses the harvest calendar to create urgency around a short-lived seasonal product. | G7: https://www.jidvei.ro/jidvei-da-startul-editiei-2024-a-campaniei-must-de-la-jidvei/
A8: Jidvei | B8: 2024 | C8: Eu sunt Jidvei. Născut în inima Transilvaniei | D8: Masterbrand / origin | E8: Corporate brand platform centered on Transylvanian provenance | F8: Provides a unifying identity platform across products, people and place. | G8: https://www.jidvei.ro/eu-sunt-jidvei-nascut-in-inima-transilvaniei-desavarsit-in-tara-vinului/
A9: Jidvei | B9: 2025–2026 | C9: Official-wine and cultural-event partnerships | D9: Events / hospitality | E9: IMPACT Bucharest official wine and RAPSODIILE concert at Castel Bethlen-Haller | F9: Turns hospitality and cultural events into premium brand experiences. | G9: https://www.jidvei.ro/grand-palais-gazduieste-literatura-romana-jidvei-o-insoteste-la-festivalul-de-carte-de-la-paris/
A10: Jidvei | B10: Feb. 2021 | C10: Mysterium extended into super-premium sparkling | D10: Product launch | E10: Traditional-method sparkling added to the existing Mysterium range | F10: Stretches an established premium name into a new category instead of creating one, which is the cheaper way to enter sparkling. | G10: https://www.jidvei.ro/de-azi-mysterium-inseamna-si-vinuri-spumante-super-premium-obtinute-prin-metoda-traditionala/
A11: Jidvei | B11: Mar. 2021 | C11: „Vin și Gust” | D11: Gastronomy partnership | E11: A project pairing the wine range with Romanian gastronomy, launched in the middle of the pandemic restaurant closures | F11: Starts a food-and-wine platform precisely when the on-trade was shut — the audience was at home and cooking. | G11: https://www.jidvei.ro/vin-si-gust-un-nou-proiect-jidvei-in-care-gastronomia-si-arta-vinului-isi-dau-mana/
A12: Jidvei | B12: Aug. 2021 | C12: „Must de la Jidvei”, seventh edition | D12: Seasonal promotion | E12: Annual harvest-season must campaign, run every year since; further editions recorded in 2023 and 2024 | F12: The only fixture in the calendar that repeats identically each autumn — a habit rather than a campaign. | G12: https://www.jidvei.ro/jidvei-da-startul-celei-de-a-saptea-editii-a-campaniei-must-de-la-jidvei/
... A266: SERVE Ceptura | B266: Feb.–Mar. 2026 | C266: Fetească Neagră content and „Making of SERVE wine” | D266: Content marketing | E266: A run of owned content on Fetească Neagră, the estate's story, a viticultural dictionary and a making-of series, published in the weeks before the Purcari deal was announced | F266: The house restates what it stands for immediately before ownership changes — the founding mission put on the record. | G266: https://www.serve.ro/

Sheet Campaign Timeline
A1: Winery | B1: Year | C1: Month | D1: Date | E1: Campaign / item | F1: Type | G1: Where it was found | H1: Source URL | J1: Coverage by winery | K1: Rows
A2: Beciul Domnesc | B2: 2023 | C2: 12 | D2: 2023-12-31 | E2: Comoara Pivniţei | F2: Brand communication | G2: Official winery news/blog | H2: https://www.beciuldomnesc.ro/list/producator/comoara-pivnitei?fc=7 | J2: Beciul Domnesc | K2: =COUNTIF($A$2:$A$511,J2) -> 3
A3: Beciul Domnesc | B3: 2023 | C3: 12 | D3: 2023-12-31 | E3: Povestea noastră | F3: Brand communication | G3: Official winery news/blog | H3: https://www.beciuldomnesc.ro/page/companie | J3: Budureasca | K3: =COUNTIF($A$2:$A$511,J3) -> 2
A4: Beciul Domnesc | B4: 2026 | E4: Beciul Domnesc lansează campania promoţională „Somelier de Grătar” împreună cu agenția Interactions | F4: Product launch | G4: IQads (Romanian marketing press); date estimated from the publisher's article sequence | H4: https://www.iqads.ro/articol/76345/beciul-domnesc-lanseaza-campania-promotionala-somelier-de-gratar-impreuna-cu | J4: Carastelec Winery | K4: =COUNTIF($A$2:$A$511,J4) -> 23
A5: Budureasca | B5: 2021 | C5: 04 | D5: 2021-04-21 | E5: Declaration on the Sustainable Development Strategy | F5: Brand communication | G5: Official winery news/blog | H5: https://budureascawines.com/declaration/ | J5: Casa de Vinuri Cotnari SA | K5: =COUNTIF($A$2:$A$511,J5) -> 0
A6: Budureasca | B6: 2026 | C6: 04 | D6: 2026-04-02 | E6: Prevenirea și reducerea risipei alimentare | F6: Promotion / contest | G6: Official winery news/blog | H6: https://budureascawines.com/ro/program-national-risipa-alimentara/ | J6: Casa de Vinuri Negrini | K6: =COUNTIF($A$2:$A$511,J6) -> 0
A7: Carastelec Winery | B7: 2021 | C7: 10 | D7: 2021-10-28 | E7: Carassia a câștigat la Londra un număr record de medalii! | F7: Awards / reputation | G7: Official winery news/blog | H7: https://www.carastelecwinery.com/ro/tripluaur-la-cswwc2021-2 | J7: Crama 1000 de Chipuri | K7: =COUNTIF($A$2:$A$511,J7) -> 0
A8: Carastelec Winery | B8: 2021 | C8: 10 | D8: 2021-10-28 | E8: Record number of medals for Carassia sparklings in London | F8: Awards / reputation | G8: Official winery news/blog | H8: https://www.carastelecwinery.com/en/triple-gold-cswwc2021-2 | J8: Crama Ceptura | K8: =COUNTIF($A$2:$A$511,J8) -> 1
A9: Carastelec Winery | B9: 2021 | C9: 10 | D9: 2021-10-28 | E9: Rekordszámú érmet szereztek a londoni Pezsgő Világbajnokságon a Carassia pezsgők | F9: Brand communication | G9: Official winery news/blog | H9: https://www.carastelecwinery.com/3arany_cswwc2021-2 | J9: Crama Gîrboiu | K9: =COUNTIF($A$2:$A$511,J9) -> 207
A10: Carastelec Winery | B10: 2021 | C10: 12 | D10: 2021-12-02 | E10: A Carassia Rosé a Pezsgő Világbajnokság egyik legrangosabb trófeáját és a Nemzeti bajnok címet is megszerezte | F10: Brand communication | G10: Official winery news/blog | H10: https://www.carastelecwinery.com/trofeak_cswwc2021 | J10: Crama Oprișor | K10: =COUNTIF($A$2:$A$511,J10) -> 0
A11: Carastelec Winery | B11: 2021 | C11: 12 | D11: 2021-12-02 | E11: Carassia Rosé Brut este anul acesta Campion Național și titular al Chairman`s Trophy. | F11: Awards / reputation | G11: Official winery news/blog | H11: https://www.carastelecwinery.com/ro/national-champion-cswwc2021 | J11: Crama Rasova | K11: =COUNTIF($A$2:$A$511,J11) -> 0
A12: Carastelec Winery | B12: 2021 | C12: 12 | D12: 2021-12-03 | E12: Carassia Rosé Brut won the Chairman’s Trophy and it is also the National Champion of Romania this year. | F12: Awards / reputation | G12: Official winery news/blog | H12: https://www.carastelecwinery.com/en/chairmans-trophy-national-champion-cswwc2021 | J12: Cramele Cotnari | K12: =COUNTIF($A$2:$A$511,J12) -> 0
A13: Carastelec Winery | B13: 2022 | C13: 09 | D13: 2022-09-16 | E13: O medalie de aur și două de argint la ediția din 2022 a Campionatului Mondial de Șampanii și Spumante din Londra | F13: Awards / reputation | G13: Official winery news/blog | H13: https://www.carastelecwinery.com/ro/cswwc2022-ro | J13: Cramele Recas | K13: =COUNTIF($A$2:$A$511,J13) -> 1
A14: Carastelec Winery | B14: 2022 | C14: 09 | D14: 2022-09-16 | E14: One gold and two silver medals at the Champagne and Sparkling Wine World Championship 2022 | F14: Awards / reputation | G14: Official winery news/blog | H14: https://www.carastelecwinery.com/en/cswwc2022-en-2 | J14: Davino Winery | K14: =COUNTIF($A$2:$A$511,J14) -> 0
A15: Carastelec Winery | B15: 2022 | C15: 09 | D15: 2022-09-16 | E15: Töretlenül folytatódik az éremgyűjtés – Egy arany, két ezüst a 2022-es Pezsgővilágbajnokságon. | F15: Brand communication | G15: Official winery news/blog | H15: https://www.carastelecwinery.com/cswwc2022-hu | J15: Domeniile Averesti | K15: =COUNTIF($A$2:$A$511,J15) -> 0
A16: Carastelec Winery | B16: 2022 | C16: 11 | D16: 2022-11-05 | E16: A new National Champion title for Carassia sparkling wines | F16: Brand communication | G16: Official winery news/blog | H16: https://www.carastelecwinery.com/en/cswwc2022-national-champion | J16: Domeniile Davidescu | K16: =COUNTIF($A$2:$A$511,J16) -> 34
... A29: Carastelec Winery | B29: 2025 | C29: 11 | D29: 2025-11-13 | E29: Carassia, medaliată constant la CSWWC | F29: Awards / reputation | G29: Official winery news/blog | H29: https://www.carastelecwinery.com/ro/carassia-medaliata-constant-la-cswwc | J29: Tohani Romania | K29: =COUNTIF($A$2:$A$511,J29) -> 1
A30: Crama Ceptura | B30: 2021 | E30: KUBIS semnează noua campanie TV pentru Crama Ceptura “Împreună, dincolo de granițe.” | F30: Promotion / contest | G30: IQads (Romanian marketing press); date estimated from the publisher's article sequence | H30: https://www.iqads.ro/articol/57608/kubis-semneaza-noua-campanie-tv-pentru-crama-ceptura-impreuna-dincolo-de-granite | J30: Via Viticola | K30: =COUNTIF($A$2:$A$511,J30) -> 0
A31: Crama Gîrboiu | B31: 2021 | C31: 01 | D31: 2021-01-03 | E31: Crama Girboiu – O retrospectivă a anului 2020 | F31: Brand communication | G31: Official winery news/blog | H31: https://cramagirboiu.ro/blog/crama-girboiu-o-retrospectiva-a-anului-2020/ | J31: Zarea | K31: =COUNTIF($A$2:$A$511,J31) -> 8
A32: Crama Gîrboiu | B32: 2021 | C32: 01 | D32: 2021-01-19 | E32: Dry January: Un Ianuarie fără alcool? | F32: Brand communication | G32: Official winery news/blog | H32: https://cramagirboiu.ro/blog/dry-january-un-ianuarie-fara-alcool/ | J32: Total | K32: =SUM(K2:K31) -> 510
A33: Crama Gîrboiu | B33: 2021 | C33: 01 | D33: 2021-01-05 | E33: Rezoluția ta pentru anul 2021 ar putea fi să bei vinuri mai bune | F33: Brand communication | G33: Official winery news/blog | H33: https://cramagirboiu.ro/blog/vinurile-bune-fac-parte-din-rezolutia-ta-pentru-anul-2021/
A34: Crama Gîrboiu | B34: 2021 | C34: 02 | D34: 2021-02-02 | E34: Recomandări de vinuri romantice pentru Ziua Îndrăgostiților | F34: Brand communication | G34: Official winery news/blog | H34: https://cramagirboiu.ro/blog/cele-mai-romantice-vinuri-pentru-ziua-indragostitilor/
A35: Crama Gîrboiu | B35: 2021 | C35: 02 | D35: 2021-02-16 | E35: Specialități Culinare – cu ce vin le asociem anul acesta? | F35: Brand communication | G35: Official winery news/blog | H35: https://cramagirboiu.ro/blog/cu-ce-specialitati-asociem-vinurile-anul-acesta/
A36: Crama Gîrboiu | B36: 2021 | C36: 03 | D36: 2021-03-31 | E36: Care este cea mai buna Feteasca Neagra? | F36: Brand communication | G36: Official winery news/blog | H36: https://cramagirboiu.ro/blog/feteasca-neagra-ambasador/
A37: Crama Gîrboiu | B37: 2021 | C37: 03 | D37: 2021-03-16 | E37: Despre vinuri bune și barrique | F37: Brand communication | G37: Official winery news/blog | H37: https://cramagirboiu.ro/blog/barrique-si-vinurile-bune-de-la-crama-girboiu/
A38: Crama Gîrboiu | B38: 2021 | C38: 03 | D38: 2021-03-01 | E38: Sărbătorește Ziua Femeii cu Vinul LIVIA | F38: Brand communication | G38: Official winery news/blog | H38: https://cramagirboiu.ro/blog/sarbatoreste-ziua-femeii-cu-vinul-livia-in-luna-martie/
A39: Crama Gîrboiu | B39: 2021 | C39: 04 | D39: 2021-04-05 | E39: Ce este metoda traditionala? | F39: Content marketing | G39: Official winery news/blog | H39: https://cramagirboiu.ro/blog/ce-este-metoda-traditionala/
A40: Crama Gîrboiu | B40: 2021 | C40: 04 | D40: 2021-04-06 | E40: Fumé: Tot ce trebuie să știi despre Vinul Fumé | F40: Brand communication | G40: Official winery news/blog | H40: https://cramagirboiu.ro/blog/fume-tot-ce-trebuie-sa-stii-despre-vinul-fume/
A41: Crama Gîrboiu | B41: 2021 | C41: 04 | D41: 2021-04-20 | E41: Masa de Paște și vinurile românești. Află care sunt cele mai recomandate alegeri. | F41: Brand communication | G41: Official winery news/blog | H41: https://cramagirboiu.ro/blog/ce-vinuri-bem-la-masa-de-paste/
A42: Crama Gîrboiu | B42: 2021 | C42: 05 | D42: 2021-05-15 | E42: Cele mai înalte distincții pentru Crama Gîrboiu la Mundus Vini 2021! | F42: Awards / reputation | G42: Official winery news/blog | H42: https://cramagirboiu.ro/blog/cele-mai-bune-vinuri-romanesti-2021/
A43: Crama Gîrboiu | B43: 2021 | C43: 05 | D43: 2021-05-11 | E43: De Constantin și Elena, sărbătorește-i pe cei dragi cu vinurile Constantin și Petite Helena | F43: Brand communication | G43: Official winery news/blog | H43: https://cramagirboiu.ro/blog/de-constantin-si-elena-sarbatoreste-i-pe-cei-dragi-cu-vinurile-constantin-si-petite-helena/
A44: Crama Gîrboiu | B44: 2021 | C44: 05 | D44: 2021-05-04 | E44: Tamaioasa Romaneasca, o editie speciala! | F44: Brand communication | G44: Official winery news/blog | H44: https://cramagirboiu.ro/blog/bacanta-tamaioasa-romaneasca-o-editie-speciala/
... A321: Jidvei | B321: 2022 | C321: 10 | D321: 2022-10-14 | E321: Owner’s Choice – 10 ani, 5 vinuri, peste 150 de medalii. Și nu ne oprim aici… | F321: Awards / reputation | G321: Official winery news/blog | H321: https://www.jidvei.ro/owners-choice-10-ani-5-vinuri-peste-150-de-medalii/
A322: Jidvei | B322: 2023 | E322: Noua gamă de vinuri, Iluziv by Jidvei, o premieră pe piața vinului din România | F322: Awards / reputation | G322: IQads (Romanian marketing press); date estimated from the publisher's article sequence | H322: https://www.iqads.ro/articol/64374/noua-gama-de-vinuri-iluziv-by-jidvei-o-premiera-pe-piata-vinului-din-romania
A323: Jidvei | B323: 2023 | C323: 01 | D323: 2023-01-13 | E323: Platforma Cocktails by Jidvei, o inițiativă unică în România | F323: Brand communication | G323: Official winery news/blog | H323: https://www.jidvei.ro/platforma-cocktails-by-jidvei-o-initiativa-unica-in-romania/
A324: Jidvei | B324: 2023 | C324: 03 | D324: 2023-03-27 | E324: D.O.C. Jidvei este un pas mai departe în arta vinului. Și nu ne oprim aici. | F324: Brand communication | G324: Official winery news/blog | H324: https://www.jidvei.ro/d-o-c-jidvei-este-un-pas-mai-departe-in-arta-vinului-si-nu-ne-oprim-aici/
A325: Jidvei | B325: 2023 | C325: 04 | D325: 2023-04-04 | E325: Traminer Roz CIB 2018, ecoul unui an viticol de excepție | F325: Brand communication | G325: Official winery news/blog | H325: https://www.jidvei.ro/traminer-roz-cib-2018-ecoul-unui-an-viticol-de-exceptie/
A326: Jidvei | B326: 2023 | C326: 04 | D326: 2023-04-25 | E326: Vino în Țara Vinului! | F326: Brand communication | G326: Official winery news/blog | H326: https://www.jidvei.ro/vino-in-tara-vinului/
A327: Jidvei | B327: 2023 | C327: 06 | D327: 2023-06-30 | E327: Noua gamă de vinuri, Iluziv by Jidvei, o premieră pe piața vinului din România | F327: Awards / reputation | G327: Official winery news/blog | H327: https://www.jidvei.ro/noua-gama-de-vinuri-iluziv-by-jidvei-o-premiera-pe-piata-vinului-din-romania/
A328: Jidvei | B328: 2023 | C328: 07 | D328: 2023-07-14 | E328: WeinRun – o provocare lansată de Jidvei iubitorilor de sport și natură | F328: Experiential / events | G328: Official winery news/blog | H328: https://www.jidvei.ro/weinrun-o-provocare-lansata-de-jidvei-iubitorilor-de-sport-si-natura/
...

Sheet CEO Research
A1: Winery | B1: CEO / senior leader | C1: Public title | D1: Background | E1: Education — Bachelor / Master / PhD | F1: Career domains | G1: Core discipline | H1: CEO source | I1: Confidence / notes
A2: Jidvei | B2: Claudiu Necșulescu | C2: President / owner; CEO title not confirmed | D2: Engineer who moved from state machinery into trading, agriculture and the post-privatization rebuilding of Jidvei. | E2: Bachelor/equivalent: Road Vehicles / Automotive Engineering, Transilvania University of Brașov (1987). Master: not found. PhD: not found. | F2: Mechanical and automotive engineering; machinery; trade/export; agriculture; viticulture; ownership and strategy. | G2: Engineering | H2: https://www.zf.ro/who-s-who/claudiu-necsulescu-10387336 | I2: High confidence on the leader; CEO title is not publicly confirmed.
A3: Beciul Domnesc | B3: Gianina-Virginia Rusu | C3: CEO since Nov. 2023 | D3: Joined as an economist, progressed through controlling and about 18 years as CFO, then became CEO; also holds accounting, audit and tax credentials. | E3: Bachelor: Accounting and Computer Science, George Bacovia University (1998–2002). Master: not found. PhD: not found. Professional: CECCAR, CAFR, CCF. | F3: Accounting; controlling; finance/CFO; audit; tax; corporate leadership. | G3: Finance / Economics | H3: https://ro.linkedin.com/in/gianina-virginia-rusu-70736640 | I3: High confidence on CEO and career progression.
A4: Purcari Wineries | B4: Victor Bostan | C4: Founder and CEO (returned 16 Dec. 2025) | D4: Founder of the modern group with more than 35 years in wine; returned as CEO after the 2025 ownership and governance transition. | E4: Bachelor/equivalent: Wine Technology, Technical University of Moldova. Master: not found. PhD: not found. | F4: Winemaking; viticulture; wine technology; entrepreneurship; corporate strategy and governance. | G4: Wine Engineer | H4: https://purcariwineries.com/en/investors/ | I4: High confidence; current leadership confirmed by public-company sources.
A5: Cramele Recas | B5: Gheorghe Iova | C5: Co-founder / director; senior operating leader | D5: Started as a farm head at IAS Recaș, became director, helped lead privatization and growth, and also taught at the Banat agricultural university. | E5: Bachelor/equivalent: Horticulture, University of Agricultural Sciences, Cluj-Napoca; top of class (1983). Master: not found. PhD: not found. | F5: Horticulture; vineyard/farm operations; winemaking; teaching/academia; management; privatization; export. | G5: Agronomy / Horticulture | H5: https://ghidulbanatului.ro/povestea-cramelor-recas-unul-dintre-cei-mai-mari-producatori-de-vinuri-din-romania_9065.html | I5: Medium confidence on the CEO-style title; leadership is shared among founding families.
A6: Via Viticola | B6: Marius Iliev | C6: General Manager / founder-level leader | D6: Former University of Illinois Chicago academic who taught differential equations; returned to Romania and became an entrepreneur, investor and winery turnaround leader. | E6: Exact bachelor/master/PhD degrees not publicly stated in reviewed sources. Advanced mathematics training is implied by his former university teaching, but not labeled as a degree. | F6: Mathematics and academia; entrepreneurship; investment/turnaround; wine; viticulture; portfolio strategy. | G6: Academia | H6: https://www.desprevin.ro/interviu-marius-iliev-ceo-via-viticola-sarica-niculitel | I6: Medium-high confidence; the exact education level is intentionally not inferred.
A7: Budureasca | B7: Olga Miloiu | C7: CEO / General Manager since 2012 | D7: Career spans European funds, import/distribution, beverage management, sales, marketing, hospitality and general management. | E7: Bachelor/licence: International Economic Relations, ASE Bucharest (1999–2003), valedictorian. Bachelor/licence: Engineering & Management in Agricultural Tourism, Bioterra University (1996–2000). Master: not found. PhD: not found. | F7: European funds; import/distribution; beverages; sales; marketing; finance/control; hospitality; general management. | G7: Finance / Economics | H7: https://ro.linkedin.com/in/olga-miloiu-ba75537b | I7: High confidence on CEO and education.
A8: Zarea | B8: Emil Popescu | C8: President / owner | D8: Long-standing owner and president; detailed earlier career history is not publicly disclosed in reviewed sources. | E8: University POLITEHNICA of Bucharest attended/listed. Degree level and field not specified. Master: not found. PhD: not found. | F8: Ownership; beverage/FMCG; corporate strategy; acquisitions; portfolio and brand management. Engineering is possible from the university context but not asserted. | G8: Engineering | H8: https://ro.linkedin.com/in/emil-popescu-758a086 | I8: High confidence on leadership; public biographical detail is limited.
A9: Cramele Cotnari | B9: Răzvan Serghiuță | C9: Director General since Dec. 2018 | D9: Advanced from Commercial Director to Director General after a long career in the wine industry. | E9: Doctoral studies: Economics, Alexandru Ioan Cuza University of Iași. Bachelor: not publicly specified. Master: not publicly specified. | F9: Sales/commercial; general management; economics; wine/FMCG. | G9: Marketing / Sales | H9: https://ro.linkedin.com/in/razvan-serghiuta-aa985710b | I9: High confidence on the current Director General.
A10: Casa de Vinuri Cotnari SA | B10: Victor Deleanu | C10: President / Director General | D10: Second-generation leader; worked in vineyard operations and winemaking before leading the premium, dry-wine and HoReCa-focused company. | E10: Bachelor: Law, Alexandru Ioan Cuza University of Iași. Additional study: Horticulture (reported as year 2 in 2015; completion not confirmed). Master: not found. PhD: not found. | F10: Law; vineyard operations; winemaking; ownership; general management; premium wine; HoReCa strategy; family business. | G10: Law | H10: https://www.crameromania.ro/oameni/interviu-victor-deleanu-cel-mai-tanar-director-general-al-unei-crame-din-romania-crame-288.html | I10: High confidence on leadership and education; horticulture completion is not claimed.
A11: Murfatlar | B11: Cosmin Popescu | C11: Managing Partner | D11: Joined Murfatlar around 2000 and progressed through wine-sector operational and executive management into the managing-partner role. | E11: Bachelor/equivalent: Finance, Banking and Stock Exchanges. Master: not found. PhD: not found. | F11: Finance; wine production and operations; executive management; brand/export strategy; oenology judging. | G11: Finance / Economics | H11: https://www.iwcb.ro/speakers/cosmin-popescu/ | I11: Medium-high confidence on the managing-partner role and education.
A12: Domeniile Averesti | B12: Rareș Florea | C12: Country Manager; previously publicly titled CEO | D12: Commercial leader with about 18 years across financial services, production, retail and e-commerce; responsible for Romanian commercial strategy and international expansion. | E12: Bachelor/equivalent: Public Administration, University of Bucharest. Master: not found. PhD: not found. | F12: Banking and financial services; production; retail; e-commerce; commercial strategy; export; general management. | G12: Finance / Economics | H12: https://www.businessmagazin.ro/analize/agricultura/rares-florea-country-manager-domeniile-averesti-domeniul-vinului-22459506 | I12: High confidence on current operating leadership and background.
... A70: Vintruvian | B70: Marius Iliev | C70: General Manager / founder-level leader | D70: Vintruvian Estates is the group behind Via Viticola, already researched in this workbook, and the buyer of Villa Zorilor and the Prince Matei brand from Vinarte in 2019; leadership and background are recorded on the Via Viticola row. | E70: See the Via Viticola row. | F70: See the Via Viticola row. | G70: Academia | H70: https://www.vintruvianestates.com/ | I70: Cross-reference, not a separate company: listed name is the group behind Via Viticola. Its four commercial staff are filed under Via Viticola and are not double-counted here.
A72: Core discipline — one standardized value per leader: the profession they trained in or built their career on before wine, so the column can be filtered and counted. Where someone holds more than one, the documented education decides; where the education is not documented, the dominant career domain does. Permitted values: Wine Engineer · Agronomy / Horticulture · Engineering · Finance / Economics · Marketing / Sales · Law · Medicine · Academia · Entrepreneur / Owner · General Management · Not established. "Entrepreneur / Owner" means a self-made proprietor with no single prior profession on the record — it is a finding, not a gap. "Not established" means no leader was identified, or none of their background is public — that is a gap. "Wine Engineer" is reserved for documented oenology or wine-technology training; running a winery is not by itself enough. The unstandardized detail stays in the Background, Education and Career domains columns; this column never replaces them.

Sheet Commercial People
A1: Winery | B1: Person | C1: Function | D1: Current role | E1: Type | F1: Seniority | G1: Source URL | I1: Roster KPI | J1: People
A2: Purcari Wineries / Crama Ceptura | B2: Oana Patricia Drăgușin | C2: Marketing | D2: Country Marketing Manager | E2: Marketing Leadership | F2: Leadership | G2: https://ro.linkedin.com/in/oana-patricia-dr%C4%83gu%C8%99in | I2: Marketing | J2: =COUNTIF($C$2:$C$101,"Marketing") -> 34
A3: Purcari Wineries / Crama Ceptura | B3: Diana Urecheanu | C3: Marketing | D3: Trade Marketing Manager | E3: Trade Marketing | F3: Manager | G3: https://ro.linkedin.com/in/dianaurecheanu | I3: Sales | J3: =COUNTIF($C$2:$C$101,"Sales") -> 66
A4: Crama Ceptura | B4: Cătălin Velicu | C4: Sales | D4: Regional Sales Manager | E4: Regional / Area Sales | F4: Manager | G4: https://ro.linkedin.com/in/catalin-velicu-051259b9 | I4: Total | J4: =SUM(J2:J3) -> 100
A5: Purcari Wineries | B5: Veronica Moșneag | C5: Marketing | D5: Senior Marketing Manager | E5: Marketing Leadership | F5: Leadership | G5: https://vioser.md/functia-director-marketing/
A6: Purcari Wineries | B6: Adelina Palancica | C6: Marketing | D6: Brand Development Manager | E6: Brand / Product | F6: Manager | G6: https://theorg.com/org/purcari-wineries-group/teams/marketing-management | I6: Marketing type | J6: People | L6: Sales type | M6: People
A7: Purcari Wineries | B7: Anton Tofan | C7: Marketing | D7: International Brand Manager | E7: International Marketing | F7: Manager | G7: https://theorg.com/org/purcari-wineries-group/teams/marketing-management | I7: Marketing Leadership | J7: =COUNTIFS($C$2:$C$101,"Marketing",$E$2:$E$101,I7) -> 12 | L7: Commercial Leadership | M7: =COUNTIFS($C$2:$C$101,"Sales",$E$2:$E$101,L7) -> 10
A8: Purcari Wineries | B8: Maria Bezede | C8: Marketing | D8: International Marketing Manager | E8: International Marketing | F8: Manager | G8: https://md.linkedin.com/in/maria-bezede-962241215 | I8: Brand / Product | J8: =COUNTIFS($C$2:$C$101,"Marketing",$E$2:$E$101,I8) -> 9 | L8: National Sales | M8: =COUNTIFS($C$2:$C$101,"Sales",$E$2:$E$101,L8) -> 6
A9: Purcari Wineries | B9: Anton Pavlovskiy | C9: Marketing | D9: Trade Marketing Manager | E9: Trade Marketing | F9: Manager | G9: https://theorg.com/org/purcari-wineries-group/teams/marketing-operations | I9: Trade Marketing | J9: =COUNTIFS($C$2:$C$101,"Marketing",$E$2:$E$101,I9) -> 5 | L9: Regional / Area Sales | M9: =COUNTIFS($C$2:$C$101,"Sales",$E$2:$E$101,L9) -> 25
A10: Purcari Wineries | B10: Bradu Valeria | C10: Marketing | D10: Assistant Trade Marketing Manager | E10: Trade Marketing | F10: Manager | G10: https://theorg.com/org/purcari-wineries-group/teams/marketing-operations | I10: Digital / Social | J10: =COUNTIFS($C$2:$C$101,"Marketing",$E$2:$E$101,I10) -> 2 | L10: Key Accounts / Modern Trade | M10: =COUNTIFS($C$2:$C$101,"Sales",$E$2:$E$101,L10) -> 7
A11: Purcari Wineries | B11: Victoria Costovici | C11: Marketing | D11: Digital Marketing Manager | E11: Digital / Social | F11: Manager | G11: https://md.linkedin.com/in/victoria-costovici-274744213 | I11: PR / Communications | J11: =COUNTIFS($C$2:$C$101,"Marketing",$E$2:$E$101,I11) -> 2 | L11: HoReCa / On-Trade | M11: =COUNTIFS($C$2:$C$101,"Sales",$E$2:$E$101,L11) -> 4
A12: Purcari Wineries | B12: Julia Eyrich | C12: Marketing | D12: Digital Marketing Manager | E12: Digital / Social | F12: Manager | G12: https://theorg.com/org/purcari-wineries-group/teams/marketing-operations | I12: Content / Creative | J12: =COUNTIFS($C$2:$C$101,"Marketing",$E$2:$E$101,I12) -> 2 | L12: Export / International | M12: =COUNTIFS($C$2:$C$101,"Sales",$E$2:$E$101,L12) -> 5
A13: Purcari Wineries | B13: Alexandra Patrut | C13: Marketing | D13: Brand Manager | E13: Brand / Product | F13: Manager | G13: https://ro.linkedin.com/pub/dir/%2B/Patrut/ro-0-Rom%C3%A2nia | I13: International Marketing | J13: =COUNTIFS($C$2:$C$101,"Marketing",$E$2:$E$101,I13) -> 2 | L13: Distribution / Traditional Trade | M13: =COUNTIFS($C$2:$C$101,"Sales",$E$2:$E$101,L13) -> 1
A14: Purcari Wineries | C14: Sales | D14: Regional Manager - MEA & Turkey | E14: Export / International | F14: Leadership | L14: E-commerce / DTC | M14: =COUNTIFS($C$2:$C$101,"Sales",$E$2:$E$101,L14) -> 2
A15: Purcari Wineries | B15: Burcu Ateşer | C15: Sales | D15: Regional Manager - Turkey & North Cyprus | E15: Export / International | F15: Manager | G15: https://theorg.com/org/purcari-wineries-group/teams/international-operations | L15: Business Development | M15: =COUNTIFS($C$2:$C$101,"Sales",$E$2:$E$101,L15) -> 1
A16: Purcari Wineries | B16: Horodinca Vlad Dumitru | C16: Sales | D16: Area Sales Manager | E16: Regional / Area Sales | F16: Manager | G16: https://theorg.com/org/purcari-wineries-group/teams/sales-department | L16: Sales Management | M16: =COUNTIFS($C$2:$C$101,"Sales",$E$2:$E$101,L16) -> 1
A17: Purcari Wineries | B17: Dumitru Cioban | C17: Sales | D17: Sales Specialist | E17: Sales Operations | F17: Specialist | G17: https://theorg.com/org/purcari-wineries-group/teams/sales-department | L17: Sales Operations | M17: =COUNTIFS($C$2:$C$101,"Sales",$E$2:$E$101,L17) -> 4
A18: Cramele Recaș | B18: Radu Dumitrescu | C18: Marketing | D18: Marketing Director | E18: Marketing Leadership | F18: Leadership | G18: https://ro.linkedin.com/in/radu-dumitrescu-110077b
A19: Cramele Recaș | B19: Ligia-Elena Stroe | C19: Marketing | D19: Brand Manager | E19: Brand / Product | F19: Manager | G19: https://ro.linkedin.com/in/ligia-stroe
A20: Cramele Recaș | B20: Ciprian Roșca | C20: Sales | D20: Commercial Director Romania | E20: Commercial Leadership | F20: Leadership | G20: https://ro.linkedin.com/in/ciprian-rosca-94483b1a
A21: Cramele Recaș | B21: Miltiade Pietroiu | C21: Sales | D21: National Sales Director | E21: National Sales | F21: Leadership | G21: https://ro.linkedin.com/in/miltiade-pietroiu-54438717
A22: Cramele Recaș | B22: Mihai-Traian Bodoc | C22: Sales | D22: National Key Account Manager | E22: Key Accounts / Modern Trade | F22: Manager | G22: https://ro.linkedin.com/in/mihai-traian-bodoc-9b79b478
A23: Cramele Recaș | B23: Octavian Macavei | C23: Sales | D23: Sales Manager | E23: Sales Management | F23: Manager | G23: https://ro.linkedin.com/in/octavian-macavei-3049a41a0
A24: Cramele Recaș | B24: Viorica Anghel | C24: Sales | D24: Sales Business Analyst | E24: Sales Operations | F24: Specialist | G24: https://ro.linkedin.com/company/cramele-recas
A25: Cramele Recaș | B25: Eduard Raznic | C25: Sales | D25: Regional Manager | E25: Regional / Area Sales | F25: Manager | G25: https://ro.linkedin.com/in/eduard-raznic-940b3232
A26: Jidvei | B26: Cristian Fuga | C26: Marketing | D26: Marketing Director | E26: Marketing Leadership | F26: Leadership | G26: https://ro.linkedin.com/in/cristian-fuga-53773948
A27: Jidvei | B27: Ana Necșulescu | C27: Marketing | D27: Communications Director | E27: PR / Communications | F27: Leadership | G27: https://ro.linkedin.com/in/ananecsulescu
A28: Jidvei | B28: Mihai Bălănescu | C28: Sales | D28: Sales Director | E28: Commercial Leadership | F28: Leadership | G28: https://ro.linkedin.com/in/mihai-balanescu-88044724
A29: Jidvei | B29: Marius Stancu | C29: Sales | D29: Export Director | E29: Export / International | F29: Leadership | G29: https://ro.linkedin.com/in/marius-stancu-72184650
... A101: Fautor | B101: Ruxanda Lipcan | C101: Sales | D101: Sales & Marketing Director | E101: Commercial Leadership | F101: Leadership | G101: https://wineofmoldova.com/en/fautor-winery/

Sheet Commercial Type Split
A1: Winery | B1: Marketing | J1: Sales | V1: Total People
B2: Marketing Leadership | C2: Brand / Product | D2: Trade Marketing | E2: Digital / Social | F2: PR / Communications | G2: Content / Creative | H2: International Marketing | I2: Total Marketing | J2: Commercial Leadership | K2: National Sales | L2: Regional / Area Sales | M2: Key Accounts / Modern Trade | N2: HoReCa / On-Trade | O2: Export / International | P2: Distribution / Traditional Trade | Q2: E-commerce / DTC | R2: Business Development | S2: Sales Management | T2: Sales Operations | U2: Total Sales
A3: Purcari Wineries | B3: =COUNTIFS('Commercial People'!$A$2:$A$101,"Purcari Wineries",'Commercial People'!$C$2:$C$101,"Marketing",'Commercial People'!$E$2:$E$101,B$2)+COUNTIFS('Commercial People'!$A$2:$A$101,"Purcari Wineries / Crama Ceptura",'Commercial People'!$C$2:$C$101,"Marketing",'Commercial People'!$E$2:$E$101,B$2) -> 2 | C3: =COUNTIFS('Commercial People'!$A$2:$A$101,"Purcari Wineries",'Commercial People'!$C$2:$C$101,"Marketing",'Commercial People'!$E$2:$E$101,C$2)+COUNTIFS('Commercial People'!$A$2:$A$101,"Purcari Wineries / Crama Ceptura",'Commercial People'!$C$2:$C$101,"Marketing",'Commercial People'!$E$2:$E$101,C$2) -> 2 | D3: =COUNTIFS('Commercial People'!$A$2:$A$101,"Purcari Wineries",'Commercial People'!$C$2:$C$101,"Marketing",'Commercial People'!$E$2:$E$101,D$2)+COUNTIFS('Commercial People'!$A$2:$A$101,"Purcari Wineries / Crama Ceptura",'Commercial People'!$C$2:$C$101,"Marketing",'Commercial People'!$E$2:$E$101,D$2) -> 3 | E3: =COUNTIFS('Commercial People'!$A$2:$A$101,"Purcari Wineries",'Commercial People'!$C$2:$C$101,"Marketing",'Commercial People'!$E$2:$E$101,E$2)+COUNTIFS('Commercial People'!$A$2:$A$101,"Purcari Wineries / Crama Ceptura",'Commercial People'!$C$2:$C$101,"Marketing",'Commercial People'!$E$2:$E$101,E$2) -> 2 | F3: =COUNTIFS('Commercial People'!$A$2:$A$101,"Purcari Wineries",'Commercial People'!$C$2:$C$101,"Marketing",'Commercial People'!$E$2:$E$101,F$2)+COUNTIFS('Commercial People'!$A$2:$A$101,"Purcari Wineries / Crama Ceptura",'Commercial People'!$C$2:$C$101,"Marketing",'Commercial People'!$E$2:$E$101,F$2) -> 0 | G3: =COUNTIFS('Commercial People'!$A$2:$A$101,"Purcari Wineries",'Commercial People'!$C$2:$C$101,"Marketing",'Commercial People'!$E$2:$E$101,G$2)+COUNTIFS('Commercial People'!$A$2:$A$101,"Purcari Wineries / Crama Ceptura",'Commercial People'!$C$2:$C$101,"Marketing",'Commercial People'!$E$2:$E$101,G$2) -> 0 | H3: =COUNTIFS('Commercial People'!$A$2:$A$101,"Purcari Wineries",'Commercial People'!$C$2:$C$101,"Marketing",'Commercial People'!$E$2:$E$101,H$2)+COUNTIFS('Commercial People'!$A$2:$A$101,"Purcari Wineries / Crama Ceptura",'Commercial People'!$C$2:$C$101,"Marketing",'Commercial People'!$E$2:$E$101,H$2) -> 2 | I3: =SUM(B3:H3) -> 11 | J3: =COUNTIFS('Commercial People'!$A$2:$A$101,"Purcari Wineries",'Commercial People'!$C$2:$C$101,"Sales",'Commercial People'!$E$2:$E$101,J$2)+COUNTIFS('Commercial People'!$A$2:$A$101,"Purcari Wineries / Crama Ceptura",'Commercial People'!$C$2:$C$101,"Sales",'Commercial People'!$E$2:$E$101,J$2) -> 0 | K3: =COUNTIFS('Commercial People'!$A$2:$A$101,"Purcari Wineries",'Commercial People'!$C$2:$C$101,"Sales",'Commercial People'!$E$2:$E$101,K$2)+COUNTIFS('Commercial People'!$A$2:$A$101,"Purcari Wineries / Crama Ceptura",'Commercial People'!$C$2:$C$101,"Sales",'Commercial People'!$E$2:$E$101,K$2) -> 0 | L3: =COUNTIFS('Commercial People'!$A$2:$A$101,"Purcari Wineries",'Commercial People'!$C$2:$C$101,"Sales",'Commercial People'!$E$2:$E$101,L$2)+COUNTIFS('Commercial People'!$A$2:$A$101,"Purcari Wineries / Crama Ceptura",'Commercial People'!$C$2:$C$101,"Sales",'Commercial People'!$E$2:$E$101,L$2) -> 1 | M3: =COUNTIFS('Commercial People'!$A$2:$A$101,"Purcari Wineries",'Commercial People'!$C$2:$C$101,"Sales",'Commercial People'!$E$2:$E$101,M$2)+COUNTIFS('Commercial People'!$A$2:$A$101,"Purcari Wineries / Crama Ceptura",'Commercial People'!$C$2:$C$101,"Sales",'Commercial People'!$E$2:$E$101,M$2) -> 0 | N3: =COUNTIFS('Commercial People'!$A$2:$A$101,"Purcari Wineries",'Commercial People'!$C$2:$C$101,"Sales",'Commercial People'!$E$2:$E$101,N$2)+COUNTIFS('Commercial People'!$A$2:$A$101,"Purcari Wineries / Crama Ceptura",'Commercial People'!$C$2:$C$101,"Sales",'Commercial People'!$E$2:$E$101,N$2) -> 0 | O3: =COUNTIFS('Commercial People'!$A$2:$A$101,"Purcari Wineries",'Commercial People'!$C$2:$C$101,"Sales",'Commercial People'!$E$2:$E$101,O$2)+COUNTIFS('Commercial People'!$A$2:$A$101,"Purcari Wineries / Crama Ceptura",'Commercial People'!$C$2:$C$101,"Sales",'Commercial People'!$E$2:$E$101,O$2) -> 2 | P3: =COUNTIFS('Commercial People'!$A$2:$A$101,"Purcari Wineries",'Commercial People'!$C$2:$C$101,"Sales",'Commercial People'!$E$2:$E$101,P$2)+COUNTIFS('Commercial People'!$A$2:$A$101,"Purcari Wineries / Crama Ceptura",'Commercial People'!$C$2:$C$101,"Sales",'Commercial People'!$E$2:$E$101,P$2) -> 0 | Q3: =COUNTIFS('Commercial People'!$A$2:$A$101,"Purcari Wineries",'Commercial People'!$C$2:$C$101,"Sales",'Commercial People'!$E$2:$E$101,Q$2)+COUNTIFS('Commercial People'!$A$2:$A$101,"Purcari Wineries / Crama Ceptura",'Commercial People'!$C$2:$C$101,"Sales",'Commercial People'!$E$2:$E$101,Q$2) -> 0 | ... T3: =COUNTIFS('Commercial People'!$A$2:$A$101,"Purcari Wineries",'Commercial People'!$C$2:$C$101,"Sales",'Commercial People'!$E$2:$E$101,T$2)+COUNTIFS('Commercial People'!$A$2:$A$101,"Purcari Wineries / Crama Ceptura",'Commercial People'!$C$2:$C$101,"Sales",'Commercial People'!$E$2:$E$101,T$2) -> 1 | U3: =SUM(J3:T3) -> 4 | V3: =I3+U3 -> 15
A4: Cramele Recaș | B4: =COUNTIFS('Commercial People'!$A$2:$A$101,"Cramele Recaș",'Commercial People'!$C$2:$C$101,"Marketing",'Commercial People'!$E$2:$E$101,B$2)+COUNTIFS('Commercial People'!$A$2:$A$101,"Cramele Recaș / Murfatlar",'Commercial People'!$C$2:$C$101,"Marketing",'Commercial People'!$E$2:$E$101,B$2) -> 1 | C4: =COUNTIFS('Commercial People'!$A$2:$A$101,"Cramele Recaș",'Commercial People'!$C$2:$C$101,"Marketing",'Commercial People'!$E$2:$E$101,C$2)+COUNTIFS('Commercial People'!$A$2:$A$101,"Cramele Recaș / Murfatlar",'Commercial People'!$C$2:$C$101,"Marketing",'Commercial People'!$E$2:$E$101,C$2) -> 1 | D4: =COUNTIFS('Commercial People'!$A$2:$A$101,"Cramele Recaș",'Commercial People'!$C$2:$C$101,"Marketing",'Commercial People'!$E$2:$E$101,D$2)+COUNTIFS('Commercial People'!$A$2:$A$101,"Cramele Recaș / Murfatlar",'Commercial People'!$C$2:$C$101,"Marketing",'Commercial People'!$E$2:$E$101,D$2) -> 0 | E4: =COUNTIFS('Commercial People'!$A$2:$A$101,"Cramele Recaș",'Commercial People'!$C$2:$C$101,"Marketing",'Commercial People'!$E$2:$E$101,E$2)+COUNTIFS('Commercial People'!$A$2:$A$101,"Cramele Recaș / Murfatlar",'Commercial People'!$C$2:$C$101,"Marketing",'Commercial People'!$E$2:$E$101,E$2) -> 0 | F4: =COUNTIFS('Commercial People'!$A$2:$A$101,"Cramele Recaș",'Commercial People'!$C$2:$C$101,"Marketing",'Commercial People'!$E$2:$E$101,F$2)+COUNTIFS('Commercial People'!$A$2:$A$101,"Cramele Recaș / Murfatlar",'Commercial People'!$C$2:$C$101,"Marketing",'Commercial People'!$E$2:$E$101,F$2) -> 0 | G4: =COUNTIFS('Commercial People'!$A$2:$A$101,"Cramele Recaș",'Commercial People'!$C$2:$C$101,"Marketing",'Commercial People'!$E$2:$E$101,G$2)+COUNTIFS('Commercial People'!$A$2:$A$101,"Cramele Recaș / Murfatlar",'Commercial People'!$C$2:$C$101,"Marketing",'Commercial People'!$E$2:$E$101,G$2) -> 0 | H4: =COUNTIFS('Commercial People'!$A$2:$A$101,"Cramele Recaș",'Commercial People'!$C$2:$C$101,"Marketing",'Commercial People'!$E$2:$E$101,H$2)+COUNTIFS('Commercial People'!$A$2:$A$101,"Cramele Recaș / Murfatlar",'Commercial People'!$C$2:$C$101,"Marketing",'Commercial People'!$E$2:$E$101,H$2) -> 0 | I4: =SUM(B4:H4) -> 2 | J4: =COUNTIFS('Commercial People'!$A$2:$A$101,"Cramele Recaș",'Commercial People'!$C$2:$C$101,"Sales",'Commercial People'!$E$2:$E$101,J$2)+COUNTIFS('Commercial People'!$A$2:$A$101,"Cramele Recaș / Murfatlar",'Commercial People'!$C$2:$C$101,"Sales",'Commercial People'!$E$2:$E$101,J$2) -> 1 | K4: =COUNTIFS('Commercial People'!$A$2:$A$101,"Cramele Recaș",'Commercial People'!$C$2:$C$101,"Sales",'Commercial People'!$E$2:$E$101,K$2)+COUNTIFS('Commercial People'!$A$2:$A$101,"Cramele Recaș / Murfatlar",'Commercial People'!$C$2:$C$101,"Sales",'Commercial People'!$E$2:$E$101,K$2) -> 2 | L4: =COUNTIFS('Commercial People'!$A$2:$A$101,"Cramele Recaș",'Commercial People'!$C$2:$C$101,"Sales",'Commercial People'!$E$2:$E$101,L$2)+COUNTIFS('Commercial People'!$A$2:$A$101,"Cramele Recaș / Murfatlar",'Commercial People'!$C$2:$C$101,"Sales",'Commercial People'!$E$2:$E$101,L$2) -> 1 | M4: =COUNTIFS('Commercial People'!$A$2:$A$101,"Cramele Recaș",'Commercial People'!$C$2:$C$101,"Sales",'Commercial People'!$E$2:$E$101,M$2)+COUNTIFS('Commercial People'!$A$2:$A$101,"Cramele Recaș / Murfatlar",'Commercial People'!$C$2:$C$101,"Sales",'Commercial People'!$E$2:$E$101,M$2) -> 1 | N4: =COUNTIFS('Commercial People'!$A$2:$A$101,"Cramele Recaș",'Commercial People'!$C$2:$C$101,"Sales",'Commercial People'!$E$2:$E$101,N$2)+COUNTIFS('Commercial People'!$A$2:$A$101,"Cramele Recaș / Murfatlar",'Commercial People'!$C$2:$C$101,"Sales",'Commercial People'!$E$2:$E$101,N$2) -> 0 | O4: =COUNTIFS('Commercial People'!$A$2:$A$101,"Cramele Recaș",'Commercial People'!$C$2:$C$101,"Sales",'Commercial People'!$E$2:$E$101,O$2)+COUNTIFS('Commercial People'!$A$2:$A$101,"Cramele Recaș / Murfatlar",'Commercial People'!$C$2:$C$101,"Sales",'Commercial People'!$E$2:$E$101,O$2) -> 0 | P4: =COUNTIFS('Commercial People'!$A$2:$A$101,"Cramele Recaș",'Commercial People'!$C$2:$C$101,"Sales",'Commercial People'!$E$2:$E$101,P$2)+COUNTIFS('Commercial People'!$A$2:$A$101,"Cramele Recaș / Murfatlar",'Commercial People'!$C$2:$C$101,"Sales",'Commercial People'!$E$2:$E$101,P$2) -> 0 | Q4: =COUNTIFS('Commercial People'!$A$2:$A$101,"Cramele Recaș",'Commercial People'!$C$2:$C$101,"Sales",'Commercial People'!$E$2:$E$101,Q$2)+COUNTIFS('Commercial People'!$A$2:$A$101,"Cramele Recaș / Murfatlar",'Commercial People'!$C$2:$C$101,"Sales",'Commercial People'!$E$2:$E$101,Q$2) -> 0 | ... T4: =COUNTIFS('Commercial People'!$A$2:$A$101,"Cramele Recaș",'Commercial People'!$C$2:$C$101,"Sales",'Commercial People'!$E$2:$E$101,T$2)+COUNTIFS('Commercial People'!$A$2:$A$101,"Cramele Recaș / Murfatlar",'Commercial People'!$C$2:$C$101,"Sales",'Commercial People'!$E$2:$E$101,T$2) -> 1 | U4: =SUM(J4:T4) -> 7 | V4: =I4+U4 -> 9
A5: Jidvei | B5: =COUNTIFS('Commercial People'!$A$2:$A$101,"Jidvei",'Commercial People'!$C$2:$C$101,"Marketing",'Commercial People'!$E$2:$E$101,B$2) -> 1 | C5: =COUNTIFS('Commercial People'!$A$2:$A$101,"Jidvei",'Commercial People'!$C$2:$C$101,"Marketing",'Commercial People'!$E$2:$E$101,C$2) -> 0 | D5: =COUNTIFS('Commercial People'!$A$2:$A$101,"Jidvei",'Commercial People'!$C$2:$C$101,"Marketing",'Commercial People'!$E$2:$E$101,D$2) -> 0 | E5: =COUNTIFS('Commercial People'!$A$2:$A$101,"Jidvei",'Commercial People'!$C$2:$C$101,"Marketing",'Commercial People'!$E$2:$E$101,E$2) -> 0 | F5: =COUNTIFS('Commercial People'!$A$2:$A$101,"Jidvei",'Commercial People'!$C$2:$C$101,"Marketing",'Commercial People'!$E$2:$E$101,F$2) -> 1 | G5: =COUNTIFS('Commercial People'!$A$2:$A$101,"Jidvei",'Commercial People'!$C$2:$C$101,"Marketing",'Commercial People'!$E$2:$E$101,G$2) -> 0 | H5: =COUNTIFS('Commercial People'!$A$2:$A$101,"Jidvei",'Commercial People'!$C$2:$C$101,"Marketing",'Commercial People'!$E$2:$E$101,H$2) -> 0 | I5: =SUM(B5:H5) -> 2 | J5: =COUNTIFS('Commercial People'!$A$2:$A$101,"Jidvei",'Commercial People'!$C$2:$C$101,"Sales",'Commercial People'!$E$2:$E$101,J$2) -> 1 | K5: =COUNTIFS('Commercial People'!$A$2:$A$101,"Jidvei",'Commercial People'!$C$2:$C$101,"Sales",'Commercial People'!$E$2:$E$101,K$2) -> 0 | L5: =COUNTIFS('Commercial People'!$A$2:$A$101,"Jidvei",'Commercial People'!$C$2:$C$101,"Sales",'Commercial People'!$E$2:$E$101,L$2) -> 2 | M5: =COUNTIFS('Commercial People'!$A$2:$A$101,"Jidvei",'Commercial People'!$C$2:$C$101,"Sales",'Commercial People'!$E$2:$E$101,M$2) -> 0 | N5: =COUNTIFS('Commercial People'!$A$2:$A$101,"Jidvei",'Commercial People'!$C$2:$C$101,"Sales",'Commercial People'!$E$2:$E$101,N$2) -> 0 | O5: =COUNTIFS('Commercial People'!$A$2:$A$101,"Jidvei",'Commercial People'!$C$2:$C$101,"Sales",'Commercial People'!$E$2:$E$101,O$2) -> 1 | P5: =COUNTIFS('Commercial People'!$A$2:$A$101,"Jidvei",'Commercial People'!$C$2:$C$101,"Sales",'Commercial People'!$E$2:$E$101,P$2) -> 0 | Q5: =COUNTIFS('Commercial People'!$A$2:$A$101,"Jidvei",'Commercial People'!$C$2:$C$101,"Sales",'Commercial People'!$E$2:$E$101,Q$2) -> 0 | ... T5: =COUNTIFS('Commercial People'!$A$2:$A$101,"Jidvei",'Commercial People'!$C$2:$C$101,"Sales",'Commercial People'!$E$2:$E$101,T$2) -> 1 | U5: =SUM(J5:T5) -> 5 | V5: =I5+U5 -> 7
